Workbook

Sheet Задание
B2: Предприятие выпускает и реализует котлеты киевские, цыплята фаршированные, пельмени.
B6: Производство организовано в цехах:
B7: №1. В разделочном цехе выполняют операции по производству фарша
B8: №2. В цехе мучных заготовок выполняют операции по производству теста и выпечки блинов
B9: №3. В цехе готовой продукции выполняют операции по производству готовой продукции
B12: Определить потребность в материалах на период с учетом данных, представленных на листах "Основные данные", "Остатки материалов", "Заказы клиентов"

Sheet ОсновныеДанные
A2: 1. | B2: Спецификация "Фарш говяжий" | C2: 1 кг | F2: Технологическая карта "Фарш говяжий" | H2: 100 кг
B3: Материал | C3: норма | D3: ед.изм. | F3: операция | G3: цех | H3: трудоем., чел-час | I3: станкоемк., маш-ч | J3: оборудование | K3: материалы
B4: говядина | C4: 0.8 | D4: кг | F4: разрезка мяса на куски | G4: №1 | H4: 5 | I4: 5 | J4: оборудование 1 | K4: по спецификации
B5: яйцо | C5: 2 | D5: шт. | F5: приготовление фарша | G5: №1 | H5: 2 | I5: 2 | J5: оборудование 2
B6: лук репчатый | C6: 0.02 | D6: кг
B7: перец | C7: 0.001 | D7: кг
B8: соль | C8: 0.001 | D8: кг
A11: 2. | B11: Спецификация "Фарш домашний" | C11: 1 кг | F11: Технологическая карта "Фарш домашний" | H11: 100 кг
B12: Материал | C12: норма | D12: ед.изм. | F12: операция | G12: цех | H12: трудоем., чел-час | I12: станкоемк., маш-ч | J12: оборудование | K12: материалы
B13: говядина | C13: 0.6 | D13: кг | F13: разрезка мяса на куски | G13: №1 | H13: 5 | I13: 5 | J13: оборудование 1 | K13: по спецификации
B14: Свинина | C14: 0.2 | D14: кг | F14: приготовление фарша | G14: №1 | H14: 2 | I14: 2 | J14: оборудование 2
B15: яйцо | C15: 2 | D15: шт.
B16: лук репчатый | C16: 0.02 | D16: кг
B17: перец | C17: 0.001 | D17: кг
B18: соль | C18: 0.001 | D18: кг
A20: 3. | B20: Спецификация "Фарш куриный" | C20: 1 кг | F20: Технологическая карта "Фарш куриный" | H20: 100 кг
B21: Материал | C21: норма | D21: ед.изм. | F21: операция | G21: цех | H21: трудоем., чел-час | I21: станкоемк., маш-ч | J21: оборудование | K21: материалы
B22: тушка цыпленка | C22: 0.6 | D22: кг | F22: разрезка мяса на куски | G22: №1 | H22: 4 | I22: 4 | J22: оборудование 1 | K22: по спецификации
B23: яйцо | C23: 2 | D23: шт. | F23: приготовление фарша | G23: №1 | H23: 1.5 | I23: 1.5 | J23: оборудование 2
B24: лук репчатый | C24: 0.02 | D24: кг
B25: перец | C25: 0.001 | D25: кг
B26: соль | C26: 0.001 | D26: кг
A28: 4. | B28: Спецификация "Тесто" | C28: 1 кг | F28: Технологическая карта "Тесто" | H28: 10 кг
B29: Материал | C29: норма | D29: ед.изм. | F29: операция | G29: цех | H29: трудоем., чел-час | I29: станкоемк., маш-ч | J29: оборудование | K29: материалы
B30: мука | C30: 0.9 | D30: кг | F30: приготовление теста | G30: №2 | H30: 2 | I30: 2 | J30: оборудование 3 | K30: по спецификации
B31: яйцо | C31: 1 | D31: шт.
B32: сахар | C32: 0.02 | D32: кг
B33: соль | C33: 0.002 | D33: кг
B34: разрыхлитель для теста | C34: 0.003 | D34: кг
A35: 5. | B35: Спецификация "Пельмени из говядины" | C35: 1 кг | F35: Технологическая карта "Пельмени из говядины" | H35: 10кг
B36: Материал | C36: норма | D36: ед.изм. | F36: операция | G36: цех | H36: трудоем., чел-час | I36: станкоемк., маш-ч | J36: оборудование | K36: материалы
B37: Фарш говяжий | C37: 0.7 | D37: кг | F37: Лепка пельменей | G37: №3 | H37: 0.5 | I37: 0.5 | J37: оборудование 4 | K37: Фарш говяжий, тесто
B38: Тесто | C38: 0.3 | D38: кг. | F38: Заморозка пельменей | G38: №3 | I38: 3 | J38: оборудование 5
A40: 6. | B40: Спецификация "Пельмени домашние" | C40: 1 кг | F40: Технологическая карта "Пельмени домашние" | H40: 10кг
B41: Материал | C41: норма | D41: ед.изм. | F41: операция | G41: цех | H41: трудоем., чел-час | I41: станкоемк., маш-ч | J41: оборудование | K41: материалы
B42: Фарш домашний | C42: 0.7 | D42: кг | F42: Лепка пельменей | G42: №3 | H42: 0.5 | I42: 0.5 | J42: оборудование 4 | K42: Фарш домашний, тесто
B43: Тесто | C43: 0.3 | D43: кг. | F43: Заморозка пельменей | G43: №3 | I43: 3 | J43: оборудование 5
A45: 7. | B45: Спецификация "Котлета по киевски" | C45: 1 кг | F45: Технологическая карта "Котлета по киевски" | H45: 10кг
B46: Материал | C46: норма | D46: ед.изм. | F46: операция | G46: цех | H46: трудоем., чел-час | I46: станкоемк., маш-ч | J46: оборудование | K46: материалы
B47: Фарш куриный | C47: 0.8 | D47: кг | F47: Лепка котлеты | G47: №3 | H47: 1 | I47: 1 | J47: оборудование 4 | K47: Фарш куриный, масло сливочное, петрушка
...

Sheet ЗаказыКлиентов
B3: Заказы клиентов
B4: Котлеты по киевски | C4: 400 | D4: кг.
B5: Фарш куриный | C5: 150 | D5: кг.
B6: Фарш домашний | C6: 350 | D6: кг.
B7: Фарш говяжий | C7: 100 | D7: кг.
B8: Цыпленок фаршированный | C8: 100 | D8: кг.
B9: Блины | C9: 50 | D9: кг.

Sheet СкладОстатки
A2: 1. | B2: Остатки на начало периода готовой продукции | C2: Кол-во | D2: ед.изм.
B3: Котлеты киевские | C3: 10 | D3: кг
B4: Цыплята фаршированные | C4: 0 | D4: кг
B5: пельмени домашние | C5: 10 | D5: кг
A7: 2. | B7: Политика запасов готовой продукции
B8: На конец периода запас должен составлять % от потребности текущего периода | C8: 20 | E8: =C8/100 -> 0.2
A10: 3. | B10: Остатки на начало периода полуфабрикатов
B11: фарш домашний | C11: 40 | D11: кг
B12: блины | C12: 10 | D12: кг
B13: фарш куриный | C13: 20 | D13: кг
A15: 4. | B15: Политика запасов полуфабрикатов
B16: На конец периода запас должен составлять % от потребности текущего периода | C16: 20 | E16: =C16/100 -> 0.2
A18: 5. | B18: Остатки на начало периода материалов
B19: говядина | C19: 60 | D19: кг
B20: свинина | C20: 2 | D20: кг
B21: цыплята | C21: 70 | D21: кг
B22: яйцо | C22: 80 | D22: шт
B23: лук репчатый | C23: 5 | D23: кг
B24: перец черный | C24: 2 | D24: кг
B25: мука | C25: 50 | D25: кг
B26: соль | C26: 10 | D26: кг
B27: разрыхлитель для теста | C27: 90 | D27: гр
B28: лук зеленый | C28: 10 | D28: кг
B29: петрушка свежая | C29: 5 | D29: кг
A31: 6. | B31: Политика запасов материалов
B32: На конец периода запас должен составлять % от потребности текущего периода | C32: 30 | E32: =C32/100 -> 0.3

Sheet Лабораторная работа №5
B2: Уровень 0 | M2: Единицы измерения
B3: Материал | C3: Единица измерения | D3: Остаток на начало | E3: Заказы клиентов | F3: Объем производства | G3: Объем закупки | H3: Остаток на конец | M3: кг | N3: шт | O3: м кв
B4: Котлеты по киевски | C4: ='Лабораторная работа №5'!$M$3 -> кг | D4: =СкладОстатки!C3 -> 10 | E4: =ЗаказыКлиентов!$C$4 -> 400 | F4: =E4-D4+H4 -> 470 | G4: 0 | H4: =E4*СкладОстатки!$E$8 -> 80
B5: =ЗаказыКлиентов!B8 -> Цыпленок фаршированный | C5: ='Лабораторная работа №5'!$M$3 -> кг | D5: =СкладОстатки!C4 -> 0 | E5: =ЗаказыКлиентов!$C$8 -> 100 | F5: =E5-D5+H5 -> 120 | G5: 0 | H5: =E5*СкладОстатки!$E$8 -> 20
B10: Уровень 1
B11: Материал(Полуфабрикаты) | C11: Единица измерения | D11: Остаток на начало | E11: Заказы клиентов | F11: Объем производства | G11: Объем закупки | H11: Остаток на конец | I11: Потребность на объем производства продукции верхнего уровня в полуфабрикате
B12: Блины | C12: =$M$3 -> кг | D12: =СкладОстатки!C12 -> 10 | E12: =ЗаказыКлиентов!C9 -> 50 | F12: =E12-D12+H12 -> 40 | G12: 0 | H12: =I12*СкладОстатки!$E$16 -> 0 | I12: 0
B13: =ЗаказыКлиентов!B5 -> Фарш куриный | C13: =$M$3 -> кг | D13: =СкладОстатки!C13 -> 20 | E13: =ЗаказыКлиентов!C5 -> 150 | F13: =E13+I13+H13-D13 -> 581.2 | G13: 0 | H13: =I13*СкладОстатки!$E$16 -> 75.2 | I13: =F4*ОсновныеДанные!C47 -> 376
B14: =ЗаказыКлиентов!B6 -> Фарш домашний | C14: =$M$3 -> кг | D14: =СкладОстатки!C11 -> 40 | E14: =ЗаказыКлиентов!C6 -> 350 | F14: =E14+I14+H14-D14 -> 310 | G14: 0 | H14: =I14*СкладОстатки!$E$16 -> 0 | I14: 0
B15: =ЗаказыКлиентов!B7 -> Фарш говяжий | C15: =$M$3 -> кг | D15: 0 | E15: =ЗаказыКлиентов!C7 -> 100 | F15: =E15+I15+H15-D15 -> 100 | G15: 0 | H15: =I15*СкладОстатки!$E$16 -> 0 | I15: 0
B16: Тесто | C16: =M3 -> кг | D16: 0 | E16: 0 | F16: =E16+I16+H16-D16 -> 38.4 | G16: 0 | H16: =I16*СкладОстатки!$E$16 -> 6.4 | I16: =F12*ОсновныеДанные!C54 -> 32
B23: Уровень 2
B24: Материал(Материалы) | C24: Единица измерения | D24: Остаток на начало | E24: Заказы клиентов | F24: Объем производства | G24: Объем закупки | H24: Остаток на конец | I24: Потребность на объем производства продукции верхнего уровня в материале
B25: Масло сливочное | C25: =$M$3 -> кг | D25: 0 | E25: 0 | F25: 0 | G25: =I25-D25+H25 -> 132.6 | H25: =I25*СкладОстатки!$E$32 -> 30.6 | I25: =F12*ОсновныеДанные!C55+F4*ОсновныеДанные!C48 -> 102 | J25: котлеты по киевски + блины
B26: тушка цыпленка | C26: =$M$3 -> кг | D26: =СкладОстатки!C21 -> 70 | E26: 0 | F26: 0 | G26: =I26-D26+H26 -> 508.136 | H26: =I26*СкладОстатки!$E$32 -> 133.416 | I26: =F13*ОсновныеДанные!C22 + F5*ОсновныеДанные!C59 -> 444.72 | J26: фарш куриный + цыпленок фаршированный
B27: яйцо | C27: =$N$3 -> шт | D27: =СкладОстатки!C22 -> 80 | E27: 0 | F27: 0 | G27: =_xlfn.CEILING.MATH(I27-D27+H27) -> 2548 | H27: =_xlfn.CEILING.MATH(I27*СкладОстатки!$E$32) -> 607 | I27: =F13*ОсновныеДанные!C23 + F16*ОсновныеДанные!C31 + F15*ОсновныеДанные!C5 +F14*ОсновныеДанные!C15 -> 2020.8 | J27: фарш куриный + тесто + фарш говяжий + фарш домашний
B28: лук репчатый | C28: =$M$3 -> кг | D28: =СкладОстатки!C23 -> 5 | E28: 0 | F28: 0 | G28: =I28-D28+H28 -> 20.7712 | H28: =I28*СкладОстатки!$E$32 -> 5.9472 | I28: =F13*ОсновныеДанные!C24+F14*ОсновныеДанные!C16+F15*ОсновныеДанные!C6 -> 19.824 | J28: фарш куриный + фарш говяжий + фарш домашний
B29: перец | C29: =$M$3 -> кг | D29: =0 -> 0 | E29: 0 | F29: 0 | G29: =I29-D29+H29 -> 1.28856 | H29: =I29*СкладОстатки!$E$32 -> 0.29736 | I29: =F13*ОсновныеДанные!C25+F14*ОсновныеДанные!C17+F15*ОсновныеДанные!C7 -> 0.9912 | J29: фарш куриный + фарш говяжий + фарш домашний
B30: соль | C30: =$M$3 -> кг | D30: =СкладОстатки!C26 -> 10 | E30: 0 | F30: 0 | G30: =I30-D30+H30 -> -8.6116 | H30: =I30*СкладОстатки!$E$32 -> 0.3204 | I30: =F13*ОсновныеДанные!C26+F14*ОсновныеДанные!C18+F15*ОсновныеДанные!C8+F16*ОсновныеДанные!C33 -> 1.068 | J30: фарш куриный + тесто + фарш говяжий + фарш домашний
B31: мука | C31: =$M$3 -> кг | D31: =СкладОстатки!C25 -> 50 | E31: 0 | F31: 0 | G31: =I31-D31+H31 -> -5.072 | H31: =I31*СкладОстатки!$E$32 -> 10.368 | I31: =F16*ОсновныеДанные!C30 -> 34.56 | J31: тесто
B32: сахар | C32: =$M$3 -> кг | D32: 0 | E32: 0 | F32: 0 | G32: =I32-D32+H32 -> 0.9984 | H32: =I32*СкладОстатки!$E$32 -> 0.2304 | I32: =F16*ОсновныеДанные!C32 -> 0.768 | J32: тесто
B33: разрыхлитель для теста | C33: гр | D33: =СкладОстатки!C27 -> 90 | E33: 0 | F33: 0 | G33: =I33-D33+H33 -> -89.85024 | H33: =I33*СкладОстатки!$E$32 -> 0.03456 | I33: =F16*ОсновныеДанные!C34 -> 0.1152 | J33: тесто
B34: говядина | C34: =$M$3 -> кг | D34: =СкладОстатки!C19 -> 60 | E34: 0 | F34: 0 | G34: =I34-D34+H34 -> 285.8 | H34: =I34*СкладОстатки!$E$32 -> 79.8 | I34: =F14*ОсновныеДанные!C13+F15*ОсновныеДанные!C4 -> 266 | J34: фарш говяжий + фарш домашний
B35: Свинина | C35: =$M$3 -> кг | D35: =СкладОстатки!C20 -> 2 | E35: 0 | F35: 0 | G35: =I35-D35+H35 -> 78.6 | H35: =I35*СкладОстатки!$E$32 -> 18.6 | I35: =F14*ОсновныеДанные!C14 -> 62 | J35: фарш домашний
B36: Лук зеленый | C36: =$M$3 -> кг | D36: =СкладОстатки!C28 -> 10 | E36: 0 | F36: 0 | G36: =I36-D36+H36 -> 21.2 | H36: =I36*СкладОстатки!$E$32 -> 7.2 | I36: =F5*ОсновныеДанные!C61 -> 24 | J36: цыпленок
B37: Петрушка | C37: =$M$3 -> кг | D37: =СкладОстатки!C29 -> 5 | E37: 0 | F37: 0 | G37: =I37-D37+H37 -> 25.615 | H37: =I37*СкладОстатки!$E$32 -> 7.065 | I37: =F4*ОсновныеДанные!C50+ОсновныеДанные!C62 -> 23.55 | J37: котлеты по киевски + цыпленок
B38: пленка пищевая | C38: =$O$3 -> м кв | D38: 0 | E38: 0 | F38: 0 | G38: =I38-D38+H38 -> 31.2 | H38: =I38*СкладОстатки!$E$32 -> 7.2 | I38: ='Лабораторная работа №5'!F5*ОсновныеДанные!C63 -> 24
B39: Сухари панировочные | C39: =$M$3 -> кг | D39: 0 | E39: 0 | F39: 0 | G39: =I39-D39+H39 -> 122.2 | H39: =I39*СкладОстатки!$E$32 -> 28.2 | I39: =F4*ОсновныеДанные!C49 -> 94
